Workbook

Sheet 00_Настройки
A1: Настройки квартального планирования
A3: Параметр | B3: Значение | C3: Комментарий
A4: Команда | B4: Atlas | C4: Название команды или потока
A5: Руководитель / ИТ-лид | B5: Демо-руководитель | C5: Ответственный за планирование
A6: Год | B6: 2026 | C6: Календарный год квартала
A7: Квартал | B7: 2 | C7: Номер квартала: 1, 2, 3 или 4
A8: Часов в рабочем дне | B8: 8 | C8: Используется на шаге 2 для перевода ч/д в ч/ч
A11: Настройка команды
A13: Роль | B13: Количество людей | C13: Комментарий | H13: =IF(SUM(B14:B20)>20,"Превышен лимит 20 сотрудников","")
A14: Тим-лид / техлид | B14: 1
A15: Лид по аналитике | B15: 1
A16: Аналитик | B16: 2
A17: Разработчик бэкенд | B17: 2
A18: Разработчик фронтенд | B18: 2
A19: Тестировщик | B19: 3
A20: Дизайнер | B20: 1
A22: Сотрудники команды
A23: Роль | B23: Сотрудник | C23: Аллокация | D23: Отпуск 1 с | E23: Отпуск 1 по | F23: Отпуск 1 дней | G23: Отпуск 2 с | H23: Отпуск 2 по | I23: Отпуск 2 дней | J23: Отпуск 3 с | K23: Отпуск 3 по | L23: Отпуск 3 дней
A24: Тим-лид / техлид | B24: Тим-лид / техлид 1 | C24: 1 | F24: =IF(OR(D24="",E24=""),"",IFERROR(MAX(0,NETWORKDAYS(D24,E24)-SUMPRODUCT((tblHolidays[Учитывать]="Да")*(tblHolidays[Дата]>=D24)*(tblHolidays[Дата]<=E24)*(WEEKDAY(tblHolidays[Дата],2)<=5))),"")) | I24: =IF(OR(G24="",H24=""),"",IFERROR(MAX(0,NETWORKDAYS(G24,H24)-SUMPRODUCT((tblHolidays[Учитывать]="Да")*(tblHolidays[Дата]>=G24)*(tblHolidays[Дата]<=H24)*(WEEKDAY(tblHolidays[Дата],2)<=5))),"")) | L24: =IF(OR(J24="",K24=""),"",IFERROR(MAX(0,NETWORKDAYS(J24,K24)-SUMPRODUCT((tblHolidays[Учитывать]="Да")*(tblHolidays[Дата]>=J24)*(tblHolidays[Дата]<=K24)*(WEEKDAY(tblHolidays[Дата],2)<=5))),""))
A25: Лид по аналитике | B25: Лид по аналитике 1 | C25: 1 | F25: =IF(OR(D25="",E25=""),"",IFERROR(MAX(0,NETWORKDAYS(D25,E25)-SUMPRODUCT((tblHolidays[Учитывать]="Да")*(tblHolidays[Дата]>=D25)*(tblHolidays[Дата]<=E25)*(WEEKDAY(tblHolidays[Дата],2)<=5))),"")) | I25: =IF(OR(G25="",H25=""),"",IFERROR(MAX(0,NETWORKDAYS(G25,H25)-SUMPRODUCT((tblHolidays[Учитывать]="Да")*(tblHolidays[Дата]>=G25)*(tblHolidays[Дата]<=H25)*(WEEKDAY(tblHolidays[Дата],2)<=5))),"")) | L25: =IF(OR(J25="",K25=""),"",IFERROR(MAX(0,NETWORKDAYS(J25,K25)-SUMPRODUCT((tblHolidays[Учитывать]="Да")*(tblHolidays[Дата]>=J25)*(tblHolidays[Дата]<=K25)*(WEEKDAY(tblHolidays[Дата],2)<=5))),""))
A26: Аналитик | B26: Аналитик 1 | C26: 1 | F26: =IF(OR(D26="",E26=""),"",IFERROR(MAX(0,NETWORKDAYS(D26,E26)-SUMPRODUCT((tblHolidays[Учитывать]="Да")*(tblHolidays[Дата]>=D26)*(tblHolidays[Дата]<=E26)*(WEEKDAY(tblHolidays[Дата],2)<=5))),"")) | I26: =IF(OR(G26="",H26=""),"",IFERROR(MAX(0,NETWORKDAYS(G26,H26)-SUMPRODUCT((tblHolidays[Учитывать]="Да")*(tblHolidays[Дата]>=G26)*(tblHolidays[Дата]<=H26)*(WEEKDAY(tblHolidays[Дата],2)<=5))),"")) | L26: =IF(OR(J26="",K26=""),"",IFERROR(MAX(0,NETWORKDAYS(J26,K26)-SUMPRODUCT((tblHolidays[Учитывать]="Да")*(tblHolidays[Дата]>=J26)*(tblHolidays[Дата]<=K26)*(WEEKDAY(tblHolidays[Дата],2)<=5))),""))
A27: Аналитик | B27: Аналитик 2 | C27: 1 | F27: =IF(OR(D27="",E27=""),"",IFERROR(MAX(0,NETWORKDAYS(D27,E27)-SUMPRODUCT((tblHolidays[Учитывать]="Да")*(tblHolidays[Дата]>=D27)*(tblHolidays[Дата]<=E27)*(WEEKDAY(tblHolidays[Дата],2)<=5))),"")) | I27: =IF(OR(G27="",H27=""),"",IFERROR(MAX(0,NETWORKDAYS(G27,H27)-SUMPRODUCT((tblHolidays[Учитывать]="Да")*(tblHolidays[Дата]>=G27)*(tblHolidays[Дата]<=H27)*(WEEKDAY(tblHolidays[Дата],2)<=5))),"")) | L27: =IF(OR(J27="",K27=""),"",IFERROR(MAX(0,NETWORKDAYS(J27,K27)-SUMPRODUCT((tblHolidays[Учитывать]="Да")*(tblHolidays[Дата]>=J27)*(tblHolidays[Дата]<=K27)*(WEEKDAY(tblHolidays[Дата],2)<=5))),""))
A28: Разработчик бэкенд | B28: Разработчик бэкенд 1 | C28: 1 | F28: =IF(OR(D28="",E28=""),"",IFERROR(MAX(0,NETWORKDAYS(D28,E28)-SUMPRODUCT((tblHolidays[Учитывать]="Да")*(tblHolidays[Дата]>=D28)*(tblHolidays[Дата]<=E28)*(WEEKDAY(tblHolidays[Дата],2)<=5))),"")) | I28: =IF(OR(G28="",H28=""),"",IFERROR(MAX(0,NETWORKDAYS(G28,H28)-SUMPRODUCT((tblHolidays[Учитывать]="Да")*(tblHolidays[Дата]>=G28)*(tblHolidays[Дата]<=H28)*(WEEKDAY(tblHolidays[Дата],2)<=5))),"")) | L28: =IF(OR(J28="",K28=""),"",IFERROR(MAX(0,NETWORKDAYS(J28,K28)-SUMPRODUCT((tblHolidays[Учитывать]="Да")*(tblHolidays[Дата]>=J28)*(tblHolidays[Дата]<=K28)*(WEEKDAY(tblHolidays[Дата],2)<=5))),""))
A29: Разработчик бэкенд | B29: Разработчик бэкенд 2 | C29: 1 | F29: =IF(OR(D29="",E29=""),"",IFERROR(MAX(0,NETWORKDAYS(D29,E29)-SUMPRODUCT((tblHolidays[Учитывать]="Да")*(tblHolidays[Дата]>=D29)*(tblHolidays[Дата]<=E29)*(WEEKDAY(tblHolidays[Дата],2)<=5))),"")) | I29: =IF(OR(G29="",H29=""),"",IFERROR(MAX(0,NETWORKDAYS(G29,H29)-SUMPRODUCT((tblHolidays[Учитывать]="Да")*(tblHolidays[Дата]>=G29)*(tblHolidays[Дата]<=H29)*(WEEKDAY(tblHolidays[Дата],2)<=5))),"")) | L29: =IF(OR(J29="",K29=""),"",IFERROR(MAX(0,NETWORKDAYS(J29,K29)-SUMPRODUCT((tblHolidays[Учитывать]="Да")*(tblHolidays[Дата]>=J29)*(tblHolidays[Дата]<=K29)*(WEEKDAY(tblHolidays[Дата],2)<=5))),""))
A30: Разработчик фронтенд | B30: Разработчик фронтенд 1 | C30: 1 | F30: =IF(OR(D30="",E30=""),"",IFERROR(MAX(0,NETWORKDAYS(D30,E30)-SUMPRODUCT((tblHolidays[Учитывать]="Да")*(tblHolidays[Дата]>=D30)*(tblHolidays[Дата]<=E30)*(WEEKDAY(tblHolidays[Дата],2)<=5))),"")) | I30: =IF(OR(G30="",H30=""),"",IFERROR(MAX(0,NETWORKDAYS(G30,H30)-SUMPRODUCT((tblHolidays[Учитывать]="Да")*(tblHolidays[Дата]>=G30)*(tblHolidays[Дата]<=H30)*(WEEKDAY(tblHolidays[Дата],2)<=5))),"")) | L30: =IF(OR(J30="",K30=""),"",IFERROR(MAX(0,NETWORKDAYS(J30,K30)-SUMPRODUCT((tblHolidays[Учитывать]="Да")*(tblHolidays[Дата]>=J30)*(tblHolidays[Дата]<=K30)*(WEEKDAY(tblHolidays[Дата],2)<=5))),""))
A31: Разработчик фронтенд | B31: Разработчик фронтенд 2 | C31: 1 | F31: =IF(OR(D31="",E31=""),"",IFERROR(MAX(0,NETWORKDAYS(D31,E31)-SUMPRODUCT((tblHolidays[Учитывать]="Да")*(tblHolidays[Дата]>=D31)*(tblHolidays[Дата]<=E31)*(WEEKDAY(tblHolidays[Дата],2)<=5))),"")) | I31: =IF(OR(G31="",H31=""),"",IFERROR(MAX(0,NETWORKDAYS(G31,H31)-SUMPRODUCT((tblHolidays[Учитывать]="Да")*(tblHolidays[Дата]>=G31)*(tblHolidays[Дата]<=H31)*(WEEKDAY(tblHolidays[Дата],2)<=5))),"")) | L31: =IF(OR(J31="",K31=""),"",IFERROR(MAX(0,NETWORKDAYS(J31,K31)-SUMPRODUCT((tblHolidays[Учитывать]="Да")*(tblHolidays[Дата]>=J31)*(tblHolidays[Дата]<=K31)*(WEEKDAY(tblHolidays[Дата],2)<=5))),""))
A32: Тестировщик | B32: Тестировщик 1 | C32: 1 | F32: =IF(OR(D32="",E32=""),"",IFERROR(MAX(0,NETWORKDAYS(D32,E32)-SUMPRODUCT((tblHolidays[Учитывать]="Да")*(tblHolidays[Дата]>=D32)*(tblHolidays[Дата]<=E32)*(WEEKDAY(tblHolidays[Дата],2)<=5))),"")) | I32: =IF(OR(G32="",H32=""),"",IFERROR(MAX(0,NETWORKDAYS(G32,H32)-SUMPRODUCT((tblHolidays[Учитывать]="Да")*(tblHolidays[Дата]>=G32)*(tblHolidays[Дата]<=H32)*(WEEKDAY(tblHolidays[Дата],2)<=5))),"")) | L32: =IF(OR(J32="",K32=""),"",IFERROR(MAX(0,NETWORKDAYS(J32,K32)-SUMPRODUCT((tblHolidays[Учитывать]="Да")*(tblHolidays[Дата]>=J32)*(tblHolidays[Дата]<=K32)*(WEEKDAY(tblHolidays[Дата],2)<=5))),""))
A33: Тестировщик | B33: Тестировщик 2 | C33: 1 | F33: =IF(OR(D33="",E33=""),"",IFERROR(MAX(0,NETWORKDAYS(D33,E33)-SUMPRODUCT((tblHolidays[Учитывать]="Да")*(tblHolidays[Дата]>=D33)*(tblHolidays[Дата]<=E33)*(WEEKDAY(tblHolidays[Дата],2)<=5))),"")) | I33: =IF(OR(G33="",H33=""),"",IFERROR(MAX(0,NETWORKDAYS(G33,H33)-SUMPRODUCT((tblHolidays[Учитывать]="Да")*(tblHolidays[Дата]>=G33)*(tblHolidays[Дата]<=H33)*(WEEKDAY(tblHolidays[Дата],2)<=5))),"")) | L33: =IF(OR(J33="",K33=""),"",IFERROR(MAX(0,NETWORKDAYS(J33,K33)-SUMPRODUCT((tblHolidays[Учитывать]="Да")*(tblHolidays[Дата]>=J33)*(tblHolidays[Дата]<=K33)*(WEEKDAY(tblHolidays[Дата],2)<=5))),""))
A34: Тестировщик | B34: Тестировщик 3 | C34: 1 | F34: =IF(OR(D34="",E34=""),"",IFERROR(MAX(0,NETWORKDAYS(D34,E34)-SUMPRODUCT((tblHolidays[Учитывать]="Да")*(tblHolidays[Дата]>=D34)*(tblHolidays[Дата]<=E34)*(WEEKDAY(tblHolidays[Дата],2)<=5))),"")) | I34: =IF(OR(G34="",H34=""),"",IFERROR(MAX(0,NETWORKDAYS(G34,H34)-SUMPRODUCT((tblHolidays[Учитывать]="Да")*(tblHolidays[Дата]>=G34)*(tblHolidays[Дата]<=H34)*(WEEKDAY(tblHolidays[Дата],2)<=5))),"")) | L34: =IF(OR(J34="",K34=""),"",IFERROR(MAX(0,NETWORKDAYS(J34,K34)-SUMPRODUCT((tblHolidays[Учитывать]="Да")*(tblHolidays[Дата]>=J34)*(tblHolidays[Дата]<=K34)*(WEEKDAY(tblHolidays[Дата],2)<=5))),""))
A35: Дизайнер | B35: Дизайнер 1 | C35: 1 | F35: =IF(OR(D35="",E35=""),"",IFERROR(MAX(0,NETWORKDAYS(D35,E35)-SUMPRODUCT((tblHolidays[Учитывать]="Да")*(tblHolidays[Дата]>=D35)*(tblHolidays[Дата]<=E35)*(WEEKDAY(tblHolidays[Дата],2)<=5))),"")) | I35: =IF(OR(G35="",H35=""),"",IFERROR(MAX(0,NETWORKDAYS(G35,H35)-SUMPRODUCT((tblHolidays[Учитывать]="Да")*(tblHolidays[Дата]>=G35)*(tblHolidays[Дата]<=H35)*(WEEKDAY(tblHolidays[Дата],2)<=5))),"")) | L35: =IF(OR(J35="",K35=""),"",IFERROR(MAX(0,NETWORKDAYS(J35,K35)-SUMPRODUCT((tblHolidays[Учитывать]="Да")*(tblHolidays[Дата]>=J35)*(tblHolidays[Дата]<=K35)*(WEEKDAY(tblHolidays[Дата],2)<=5))),""))
F36: =IF(OR(D36="",E36=""),"",IFERROR(MAX(0,NETWORKDAYS(D36,E36)-SUMPRODUCT((tblHolidays[Учитывать]="Да")*(tblHolidays[Дата]>=D36)*(tblHolidays[Дата]<=E36)*(WEEKDAY(tblHolidays[Дата],2)<=5))),"")) | I36: =IF(OR(G36="",H36=""),"",IFERROR(MAX(0,NETWORKDAYS(G36,H36)-SUMPRODUCT((tblHolidays[Учитывать]="Да")*(tblHolidays[Дата]>=G36)*(tblHolidays[Дата]<=H36)*(WEEKDAY(tblHolidays[Дата],2)<=5))),"")) | L36: =IF(OR(J36="",K36=""),"",IFERROR(MAX(0,NETWORKDAYS(J36,K36)-SUMPRODUCT((tblHolidays[Учитывать]="Да")*(tblHolidays[Дата]>=J36)*(tblHolidays[Дата]<=K36)*(WEEKDAY(tblHolidays[Дата],2)<=5))),""))
F37: =IF(OR(D37="",E37=""),"",IFERROR(MAX(0,NETWORKDAYS(D37,E37)-SUMPRODUCT((tblHolidays[Учитывать]="Да")*(tblHolidays[Дата]>=D37)*(tblHolidays[Дата]<=E37)*(WEEKDAY(tblHolidays[Дата],2)<=5))),"")) | I37: =IF(OR(G37="",H37=""),"",IFERROR(MAX(0,NETWORKDAYS(G37,H37)-SUMPRODUCT((tblHolidays[Учитывать]="Да")*(tblHolidays[Дата]>=G37)*(tblHolidays[Дата]<=H37)*(WEEKDAY(tblHolidays[Дата],2)<=5))),"")) | L37: =IF(OR(J37="",K37=""),"",IFERROR(MAX(0,NETWORKDAYS(J37,K37)-SUMPRODUCT((tblHolidays[Учитывать]="Да")*(tblHolidays[Дата]>=J37)*(tblHolidays[Дата]<=K37)*(WEEKDAY(tblHolidays[Дата],2)<=5))),""))
F38: =IF(OR(D38="",E38=""),"",IFERROR(MAX(0,NETWORKDAYS(D38,E38)-SUMPRODUCT((tblHolidays[Учитывать]="Да")*(tblHolidays[Дата]>=D38)*(tblHolidays[Дата]<=E38)*(WEEKDAY(tblHolidays[Дата],2)<=5))),"")) | I38: =IF(OR(G38="",H38=""),"",IFERROR(MAX(0,NETWORKDAYS(G38,H38)-SUMPRODUCT((tblHolidays[Учитывать]="Да")*(tblHolidays[Дата]>=G38)*(tblHolidays[Дата]<=H38)*(WEEKDAY(tblHolidays[Дата],2)<=5))),"")) | L38: =IF(OR(J38="",K38=""),"",IFERROR(MAX(0,NETWORKDAYS(J38,K38)-SUMPRODUCT((tblHolidays[Учитывать]="Да")*(tblHolidays[Дата]>=J38)*(tblHolidays[Дата]<=K38)*(WEEKDAY(tblHolidays[Дата],2)<=5))),""))
F39: =IF(OR(D39="",E39=""),"",IFERROR(MAX(0,NETWORKDAYS(D39,E39)-SUMPRODUCT((tblHolidays[Учитывать]="Да")*(tblHolidays[Дата]>=D39)*(tblHolidays[Дата]<=E39)*(WEEKDAY(tblHolidays[Дата],2)<=5))),"")) | I39: =IF(OR(G39="",H39=""),"",IFERROR(MAX(0,NETWORKDAYS(G39,H39)-SUMPRODUCT((tblHolidays[Учитывать]="Да")*(tblHolidays[Дата]>=G39)*(tblHolidays[Дата]<=H39)*(WEEKDAY(tblHolidays[Дата],2)<=5))),"")) | L39: =IF(OR(J39="",K39=""),"",IFERROR(MAX(0,NETWORKDAYS(J39,K39)-SUMPRODUCT((tblHolidays[Учитывать]="Да")*(tblHolidays[Дата]>=J39)*(tblHolidays[Дата]<=K39)*(WEEKDAY(tblHolidays[Дата],2)<=5))),""))
F40: =IF(OR(D40="",E40=""),"",IFERROR(MAX(0,NETWORKDAYS(D40,E40)-SUMPRODUCT((tblHolidays[Учитывать]="Да")*(tblHolidays[Дата]>=D40)*(tblHolidays[Дата]<=E40)*(WEEKDAY(tblHolidays[Дата],2)<=5))),"")) | I40: =IF(OR(G40="",H40=""),"",IFERROR(MAX(0,NETWORKDAYS(G40,H40)-SUMPRODUCT((tblHolidays[Учитывать]="Да")*(tblHolidays[Дата]>=G40)*(tblHolidays[Дата]<=H40)*(WEEKDAY(tblHolidays[Дата],2)<=5))),"")) | L40: =IF(OR(J40="",K40=""),"",IFERROR(MAX(0,NETWORKDAYS(J40,K40)-SUMPRODUCT((tblHolidays[Учитывать]="Да")*(tblHolidays[Дата]>=J40)*(tblHolidays[Дата]<=K40)*(WEEKDAY(tblHolidays[Дата],2)<=5))),""))
F41: =IF(OR(D41="",E41=""),"",IFERROR(MAX(0,NETWORKDAYS(D41,E41)-SUMPRODUCT((tblHolidays[Учитывать]="Да")*(tblHolidays[Дата]>=D41)*(tblHolidays[Дата]<=E41)*(WEEKDAY(tblHolidays[Дата],2)<=5))),"")) | I41: =IF(OR(G41="",H41=""),"",IFERROR(MAX(0,NETWORKDAYS(G41,H41)-SUMPRODUCT((tblHolidays[Учитывать]="Да")*(tblHolidays[Дата]>=G41)*(tblHolidays[Дата]<=H41)*(WEEKDAY(tblHolidays[Дата],2)<=5))),"")) | L41: =IF(OR(J41="",K41=""),"",IFERROR(MAX(0,NETWORKDAYS(J41,K41)-SUMPRODUCT((tblHolidays[Учитывать]="Да")*(tblHolidays[Дата]>=J41)*(tblHolidays[Дата]<=K41)*(WEEKDAY(tblHolidays[Дата],2)<=5))),""))
F42: =IF(OR(D42="",E42=""),"",IFERROR(MAX(0,NETWORKDAYS(D42,E42)-SUMPRODUCT((tblHolidays[Учитывать]="Да")*(tblHolidays[Дата]>=D42)*(tblHolidays[Дата]<=E42)*(WEEKDAY(tblHolidays[Дата],2)<=5))),"")) | I42: =IF(OR(G42="",H42=""),"",IFERROR(MAX(0,NETWORKDAYS(G42,H42)-SUMPRODUCT((tblHolidays[Учитывать]="Да")*(tblHolidays[Дата]>=G42)*(tblHolidays[Дата]<=H42)*(WEEKDAY(tblHolidays[Дата],2)<=5))),"")) | L42: =IF(OR(J42="",K42=""),"",IFERROR(MAX(0,NETWORKDAYS(J42,K42)-SUMPRODUCT((tblHolidays[Учитывать]="Да")*(tblHolidays[Дата]>=J42)*(tblHolidays[Дата]<=K42)*(WEEKDAY(tblHolidays[Дата],2)<=5))),""))
F43: =IF(OR(D43="",E43=""),"",IFERROR(MAX(0,NETWORKDAYS(D43,E43)-SUMPRODUCT((tblHolidays[Учитывать]="Да")*(tblHolidays[Дата]>=D43)*(tblHolidays[Дата]<=E43)*(WEEKDAY(tblHolidays[Дата],2)<=5))),"")) | I43: =IF(OR(G43="",H43=""),"",IFERROR(MAX(0,NETWORKDAYS(G43,H43)-SUMPRODUCT((tblHolidays[Учитывать]="Да")*(tblHolidays[Дата]>=G43)*(tblHolidays[Дата]<=H43)*(WEEKDAY(tblHolidays[Дата],2)<=5))),"")) | L43: =IF(OR(J43="",K43=""),"",IFERROR(MAX(0,NETWORKDAYS(J43,K43)-SUMPRODUCT((tblHolidays[Учитывать]="Да")*(tblHolidays[Дата]>=J43)*(tblHolidays[Дата]<=K43)*(WEEKDAY(tblHolidays[Дата],2)<=5))),""))

Sheet 01_Настройки квартала
A1: Настройки квартала
A3: Параметр | B3: Значение | C3: Комментарий
A4: Дата начала | B4: 46113 | C4: Первый календарный день планируемого квартала
A5: Дата завершения | B5: 46203 | C5: Последний календарный день планируемого квартала
A6: Количество рабочих дней | B6: 62 | C6: Рабочие дни по производственному календарю; заполняется вручную
A7: Будние дни по календарю | B7: =IF(OR(B4="",B5=""),"",NETWORKDAYS(B4,B5)) | C7: Автоматически: количество дней Пн-Пт между датой начала и датой завершения
A8: Праздничных дней к заполнению | B8: =IF(OR(B4="",B5="",B6=""),"",MAX(0,B7-B6)) | C8: Автоматически: будние дни по календарю минус введенное количество рабочих дней
A11: Список праздничных дней
A13: Дата | B13: Название | C13: Комментарий | D13: Учитывать
A14: =IF(OR($B$4="",ROW(A1)>$B$8),"",WORKDAY($B$4-1,ROW(A1))) | D14: =IF($A14="","","Да")
A15: =IF(OR($B$4="",ROW(A2)>$B$8),"",WORKDAY($B$4-1,ROW(A2))) | D15: =IF($A15="","","Да")
A16: =IF(OR($B$4="",ROW(A3)>$B$8),"",WORKDAY($B$4-1,ROW(A3))) | D16: =IF($A16="","","Да")
A17: =IF(OR($B$4="",ROW(A4)>$B$8),"",WORKDAY($B$4-1,ROW(A4))) | D17: =IF($A17="","","Да")
A18: =IF(OR($B$4="",ROW(A5)>$B$8),"",WORKDAY($B$4-1,ROW(A5))) | D18: =IF($A18="","","Да")
A19: =IF(OR($B$4="",ROW(A6)>$B$8),"",WORKDAY($B$4-1,ROW(A6))) | D19: =IF($A19="","","Да")
A20: =IF(OR($B$4="",ROW(A7)>$B$8),"",WORKDAY($B$4-1,ROW(A7))) | D20: =IF($A20="","","Да")
A21: =IF(OR($B$4="",ROW(A8)>$B$8),"",WORKDAY($B$4-1,ROW(A8))) | D21: =IF($A21="","","Да")
A22: =IF(OR($B$4="",ROW(A9)>$B$8),"",WORKDAY($B$4-1,ROW(A9))) | D22: =IF($A22="","","Да")
A23: =IF(OR($B$4="",ROW(A10)>$B$8),"",WORKDAY($B$4-1,ROW(A10))) | D23: =IF($A23="","","Да")
A24: =IF(OR($B$4="",ROW(A11)>$B$8),"",WORKDAY($B$4-1,ROW(A11))) | D24: =IF($A24="","","Да")
A25: =IF(OR($B$4="",ROW(A12)>$B$8),"",WORKDAY($B$4-1,ROW(A12))) | D25: =IF($A25="","","Да")
... A33: =IF(OR($B$4="",ROW(A20)>$B$8),"",WORKDAY($B$4-1,ROW(A20))) | D33: =IF($A33="","","Да")

Sheet 02_Capacity
C1: Capacity команды
C2: Команда | E2: ='00_Настройки'!B4
C3: Квартал | E3: ='00_Настройки'!B7&" квартал "&'00_Настройки'!B6
C4: ИТ-лид команды | E4: ='00_Настройки'!B5
C6: Показатель | E6: Значение | F6: Авто 00 | G6: Переопределение
C7: Количество рабочих дней в квартале | E7: ='01_Настройки квартала'!B6
C8: Количество аналитиков в команде | E8: =IF(G8="",F8,G8) | F8: =SUMIFS(tblTeamMembers[Аллокация],tblTeamMembers[Роль],"Аналитик")
C9: Количество разработчиков BE в команде | E9: =IF(G9="",F9,G9) | F9: =SUMIFS(tblTeamMembers[Аллокация],tblTeamMembers[Роль],"Разработчик бэкенд")
C10: Количество разработчиков FE в команде | E10: =IF(G10="",F10,G10) | F10: =SUMIFS(tblTeamMembers[Аллокация],tblTeamMembers[Роль],"Разработчик фронтенд")
C11: Количество тестировщиков в команде | E11: =IF(G11="",F11,G11) | F11: =SUMIFS(tblTeamMembers[Аллокация],tblTeamMembers[Роль],"Тестировщик")
C12: Тим лид команды (разработка BE/FE, тестирование) | E12: =IF(G12="",F12,G12) | F12: =SUMIFS(tblTeamMembers[Аллокация],tblTeamMembers[Роль],"Тим-лид / техлид")
C13: Лид по аналитике | E13: =IF(G13="",F13,G13) | F13: =SUMIFS(tblTeamMembers[Аллокация],tblTeamMembers[Роль],"Лид по аналитике")
C14: Отпуска аналитиков | E14: =IF(G14="",F14,G14) | F14: =IFERROR(SUMPRODUCT((tblTeamMembers[Роль]="Аналитик")*tblTeamMembers[Аллокация],tblTeamMembers[Отпуск 1 дней])+SUMPRODUCT((tblTeamMembers[Роль]="Аналитик")*tblTeamMembers[Аллокация],tblTeamMembers[Отпуск 2 дней])+SUMPRODUCT((tblTeamMembers[Роль]="Аналитик")*tblTeamMembers[Аллокация],tblTeamMembers[Отпуск 3 дней]),0)
C15: Отпуска разработчиков BE | E15: =IF(G15="",F15,G15) | F15: =IFERROR(SUMPRODUCT((tblTeamMembers[Роль]="Разработчик бэкенд")*tblTeamMembers[Аллокация],tblTeamMembers[Отпуск 1 дней])+SUMPRODUCT((tblTeamMembers[Роль]="Разработчик бэкенд")*tblTeamMembers[Аллокация],tblTeamMembers[Отпуск 2 дней])+SUMPRODUCT((tblTeamMembers[Роль]="Разработчик бэкенд")*tblTeamMembers[Аллокация],tblTeamMembers[Отпуск 3 дней]),0)
C16: Отпуска разработчиков FE | E16: =IF(G16="",F16,G16) | F16: =IFERROR(SUMPRODUCT((tblTeamMembers[Роль]="Разработчик фронтенд")*tblTeamMembers[Аллокация],tblTeamMembers[Отпуск 1 дней])+SUMPRODUCT((tblTeamMembers[Роль]="Разработчик фронтенд")*tblTeamMembers[Аллокация],tblTeamMembers[Отпуск 2 дней])+SUMPRODUCT((tblTeamMembers[Роль]="Разработчик фронтенд")*tblTeamMembers[Аллокация],tblTeamMembers[Отпуск 3 дней]),0)
C17: Отпуска тестировщиков | E17: =IF(G17="",F17,G17) | F17: =IFERROR(SUMPRODUCT((tblTeamMembers[Роль]="Тестировщик")*tblTeamMembers[Аллокация],tblTeamMembers[Отпуск 1 дней])+SUMPRODUCT((tblTeamMembers[Роль]="Тестировщик")*tblTeamMembers[Аллокация],tblTeamMembers[Отпуск 2 дней])+SUMPRODUCT((tblTeamMembers[Роль]="Тестировщик")*tblTeamMembers[Аллокация],tblTeamMembers[Отпуск 3 дней]),0)
C18: Отпуска тим лида команды (разработка BE, тестирование) | E18: =IF(G18="",F18,G18) | F18: =IFERROR(SUMPRODUCT((tblTeamMembers[Роль]="Тим-лид / техлид")*tblTeamMembers[Аллокация],tblTeamMembers[Отпуск 1 дней])+SUMPRODUCT((tblTeamMembers[Роль]="Тим-лид / техлид")*tblTeamMembers[Аллокация],tblTeamMembers[Отпуск 2 дней])+SUMPRODUCT((tblTeamMembers[Роль]="Тим-лид / техлид")*tblTeamMembers[Аллокация],tblTeamMembers[Отпуск 3 дней]),0)
C19: Отпуска лида по аналитике | E19: =IF(G19="",F19,G19) | F19: =IFERROR(SUMPRODUCT((tblTeamMembers[Роль]="Лид по аналитике")*tblTeamMembers[Аллокация],tblTeamMembers[Отпуск 1 дней])+SUMPRODUCT((tblTeamMembers[Роль]="Лид по аналитике")*tblTeamMembers[Аллокация],tblTeamMembers[Отпуск 2 дней])+SUMPRODUCT((tblTeamMembers[Роль]="Лид по аналитике")*tblTeamMembers[Аллокация],tblTeamMembers[Отпуск 3 дней]),0)
C20: Фокус-фактор основной команды | E20: 0.7 | F20: - заполняется вручную для каждой команды, рекомендуемое значение - 70%
C21: Фокус-фактор тим лида | E21: 0.5 | F21: - заполняется вручную для каждой команды
C22: Фокус-фактор лида по аналитике | E22: 0.5 | F22: - заполняется вручную для каждой команды (ограничение - не менее 50%)
C23: Количество дизайнеров | E23: =IF(G23="",F23,G23) | F23: =SUMIFS(tblTeamMembers[Аллокация],tblTeamMembers[Роль],"Дизайнер")
C24: Отпуска дизайнеров | E24: =IF(G24="",F24,G24) | F24: =IFERROR(SUMPRODUCT((tblTeamMembers[Роль]="Дизайнер")*tblTeamMembers[Аллокация],tblTeamMembers[Отпуск 1 дней])+SUMPRODUCT((tblTeamMembers[Роль]="Дизайнер")*tblTeamMembers[Аллокация],tblTeamMembers[Отпуск 2 дней])+SUMPRODUCT((tblTeamMembers[Роль]="Дизайнер")*tblTeamMembers[Аллокация],tblTeamMembers[Отпуск 3 дней]),0)
C25: Фокус-фактор дизайнеров | E25: 0.7 | F25: - заполняется вручную для дизайнеров, рекомендуемое значение - 70%
E26: ч/д | F26: ч/ч
C27: Capacity по аналитикам | E27: =IFERROR(ROUNDDOWN(((E7*E8-E14)*E20)+((E7*E13-E19)*E22),0),0) | F27: =IFERROR(E27*'00_Настройки'!B$8,0)
C28: Capacity по разработчикам BE | E28: =IFERROR(ROUNDDOWN(((E7*E9-E15)*E20)+((E7*E12-E18)*E21),0),0) | F28: =IFERROR(E28*'00_Настройки'!B$8,0)
C29: Capacity по разработчикам FE | E29: =IFERROR(ROUNDDOWN((E7*E10-E16)*E20,0),0) | F29: =IFERROR(E29*'00_Настройки'!B$8,0)
C30: Capacity по тестировщикам | E30: =IFERROR(ROUNDDOWN((E7*E11-E17)*E20,0),0) | F30: =IFERROR(E30*'00_Настройки'!B$8,0)
C32: Общее Capacity | E32: =SUM(E27:E30) | F32: =SUM(F27:F30)
C34: Capacity по дизайнерам | E34: =IFERROR(ROUNDDOWN((E7*E23-E24)*E25,0),0) | F34: =IFERROR(E34*'00_Настройки'!B$8,0)
C35: Общее Capacity с дизайнерами | E35: =E32+E34 | F35: =F32+F34

Sheet 03_Оценка задач
C1: Экспорт | D1: Импорт | E1: Оценка задач | H1: Статистика
A2: Сбросить | C2: Обновить | D2: Импорт CSV (до 100) | F2: JQL | H2: =SUM(H4:H103) | I2: =SUM(I4:I103) | J2: =SUM(J4:J103) | K2: =SUM(K4:K103) | L2: =SUM(L4:L103)
A3: > | B3: x | C3: Приоритет | D3: Направление | E3: Описание | F3: ЗНИ/Jira | G3: Примечание | H3: DE | I3: AN | J3: BE | K3: FE | L3: QA | M3: Комментарий | N3: + | O3: Экспорт
A4: > | C4: 10 | D4: Личный кабинет | E4: Единый вход для пользователей | F4: PLAN-1001 | G4: Демо | H4: 4 | I4: 3 | J4: 5 | K4: 5 | L4: 4 | N4: +
A5: > | C5: 20 | D5: Уведомления | E5: Настройка email-уведомлений | F5: PLAN-1002 | H5: 2 | I5: 4 | J5: 6 | K5: 3 | L5: 4 | N5: +
A6: > | C6: 30 | D6: Каталог | E6: Поиск и фильтрация элементов | F6: PLAN-1003 | H6: 5 | I6: 5 | J6: 8 | K6: 6 | L6: 6 | N6: +
A7: > | C7: 40 | D7: Отчётность | E7: Экспорт отчёта в XLSX | F7: PLAN-1004 | H7: 1 | I7: 3 | J7: 7 | K7: 2 | L7: 5 | N7: +
A8: > | C8: 50 | D8: Профиль | E8: Управление настройками профиля | F8: PLAN-1005 | H8: 6 | I8: 4 | J8: 5 | K8: 7 | L8: 5 | N8: +
A9: > | C9: 60 | D9: Интеграции | E9: Публичный API чтения статусов | F9: PLAN-1006 | H9: 0 | I9: 6 | J9: 10 | K9: 0 | L9: 7 | N9: +
A10: > | C10: 70 | D10: Надёжность | E10: Мониторинг фоновых операций | F10: PLAN-1007 | H10: 2 | I10: 2 | J10: 6 | K10: 2 | L10: 5 | N10: +
A11: > | C11: 80 | D11: Мобильный UX | E11: Адаптивная навигация | F11: PLAN-1008 | H11: 8 | I11: 3 | J11: 2 | K11: 8 | L11: 5 | N11: +

Sheet 04_Квартальный план
A1: Квартальный план
G2: Загрузить 03 в бэклог | J2: Емкость | K2: =ROUND('02_Capacity'!$E$34,1) | L2: =ROUND('02_Capacity'!$E$27,1) | M2: =ROUND('02_Capacity'!$E$28,1) | N2: =ROUND('02_Capacity'!$E$29,1) | O2: =ROUND('02_Capacity'!$E$30,1) | Q2: Посчитать план | R2: Экспорт плана
J3: План+риск | K3: =ROUND((SUMIFS(tblPlanActive[DE],tblPlanActive[Статус на конец квартала],"<>Отложено"))*(1+IFERROR(IF(AND(ISNUMBER(INDEX(tblPlanningRuleSettings[Значение],MATCH("RESOURCE_BALANCE_RISK_PERCENT",tblPlanningRuleSettings[Код],0))),INDEX(tblPlanningRuleSettings[Значение],MATCH("RESOURCE_BALANCE_RISK_PERCENT",tblPlanningRuleSettings[Код],0))>=0,INDEX(tblPlanningRuleSettings[Значение],MATCH("RESOURCE_BALANCE_RISK_PERCENT",tblPlanningRuleSettings[Код],0))<=1),INDEX(tblPlanningRuleSettings[Значение],MATCH("RESOURCE_BALANCE_RISK_PERCENT",tblPlanningRuleSettings[Код],0)),0.2),0.2)),1) | L3: =ROUND((SUMIFS(tblPlanActive[AN],tblPlanActive[Статус на конец квартала],"<>Отложено"))*(1+IFERROR(IF(AND(ISNUMBER(INDEX(tblPlanningRuleSettings[Значение],MATCH("RESOURCE_BALANCE_RISK_PERCENT",tblPlanningRuleSettings[Код],0))),INDEX(tblPlanningRuleSettings[Значение],MATCH("RESOURCE_BALANCE_RISK_PERCENT",tblPlanningRuleSettings[Код],0))>=0,INDEX(tblPlanningRuleSettings[Значение],MATCH("RESOURCE_BALANCE_RISK_PERCENT",tblPlanningRuleSettings[Код],0))<=1),INDEX(tblPlanningRuleSettings[Значение],MATCH("RESOURCE_BALANCE_RISK_PERCENT",tblPlanningRuleSettings[Код],0)),0.2),0.2)),1) | M3: =ROUND((SUMIFS(tblPlanActive[BE],tblPlanActive[Статус на конец квартала],"<>Готова аналитика",tblPlanActive[Статус на конец квартала],"<>Готова разработка (фронт)",tblPlanActive[Статус на конец квартала],"<>Отложено"))*(1+IFERROR(IF(AND(ISNUMBER(INDEX(tblPlanningRuleSettings[Значение],MATCH("RESOURCE_BALANCE_RISK_PERCENT",tblPlanningRuleSettings[Код],0))),INDEX(tblPlanningRuleSettings[Значение],MATCH("RESOURCE_BALANCE_RISK_PERCENT",tblPlanningRuleSettings[Код],0))>=0,INDEX(tblPlanningRuleSettings[Значение],MATCH("RESOURCE_BALANCE_RISK_PERCENT",tblPlanningRuleSettings[Код],0))<=1),INDEX(tblPlanningRuleSettings[Значение],MATCH("RESOURCE_BALANCE_RISK_PERCENT",tblPlanningRuleSettings[Код],0)),0.2),0.2)),1) | N3: =ROUND((SUMIFS(tblPlanActive[FE],tblPlanActive[Статус на конец квартала],"<>Готова аналитика",tblPlanActive[Статус на конец квартала],"<>Готова разработка (бэк)",tblPlanActive[Статус на конец квартала],"<>Отложено"))*(1+IFERROR(IF(AND(ISNUMBER(INDEX(tblPlanningRuleSettings[Значение],MATCH("RESOURCE_BALANCE_RISK_PERCENT",tblPlanningRuleSettings[Код],0))),INDEX(tblPlanningRuleSettings[Значение],MATCH("RESOURCE_BALANCE_RISK_PERCENT",tblPlanningRuleSettings[Код],0))>=0,INDEX(tblPlanningRuleSettings[Значение],MATCH("RESOURCE_BALANCE_RISK_PERCENT",tblPlanningRuleSettings[Код],0))<=1),INDEX(tblPlanningRuleSettings[Значение],MATCH("RESOURCE_BALANCE_RISK_PERCENT",tblPlanningRuleSettings[Код],0)),0.2),0.2)),1) | O3: =ROUND((SUMIFS(tblPlanActive[QA],tblPlanActive[Статус на конец квартала],"<>Готова аналитика",tblPlanActive[Статус на конец квартала],"<>Готова разработка",tblPlanActive[Статус на конец квартала],"<>Готова разработка (бэк)",tblPlanActive[Статус на конец квартала],"<>Готова разработка (фронт)",tblPlanActive[Статус на конец квартала],"<>Отложено"))*(1+IFERROR(IF(AND(ISNUMBER(INDEX(tblPlanningRuleSettings[Значение],MATCH("RESOURCE_BALANCE_RISK_PERCENT",tblPlanningRuleSettings[Код],0))),INDEX(tblPlanningRuleSettings[Значение],MATCH("RESOURCE_BALANCE_RISK_PERCENT",tblPlanningRuleSettings[Код],0))>=0,INDEX(tblPlanningRuleSettings[Значение],MATCH("RESOURCE_BALANCE_RISK_PERCENT",tblPlanningRuleSettings[Код],0))<=1),INDEX(tblPlanningRuleSettings[Значение],MATCH("RESOURCE_BALANCE_RISK_PERCENT",tblPlanningRuleSettings[Код],0)),0.2),0.2)),1)
I4: JQL | J4: Баланс | K4: =ROUND('02_Capacity'!$E$34-(SUMIFS(tblPlanActive[DE],tblPlanActive[Статус на конец квартала],"<>Отложено"))*(1+IFERROR(IF(AND(ISNUMBER(INDEX(tblPlanningRuleSettings[Значение],MATCH("RESOURCE_BALANCE_RISK_PERCENT",tblPlanningRuleSettings[Код],0))),INDEX(tblPlanningRuleSettings[Значение],MATCH("RESOURCE_BALANCE_RISK_PERCENT",tblPlanningRuleSettings[Код],0))>=0,INDEX(tblPlanningRuleSettings[Значение],MATCH("RESOURCE_BALANCE_RISK_PERCENT",tblPlanningRuleSettings[Код],0))<=1),INDEX(tblPlanningRuleSettings[Значение],MATCH("RESOURCE_BALANCE_RISK_PERCENT",tblPlanningRuleSettings[Код],0)),0.2),0.2)),1) | L4: =ROUND('02_Capacity'!$E$27-(SUMIFS(tblPlanActive[AN],tblPlanActive[Статус на конец квартала],"<>Отложено"))*(1+IFERROR(IF(AND(ISNUMBER(INDEX(tblPlanningRuleSettings[Значение],MATCH("RESOURCE_BALANCE_RISK_PERCENT",tblPlanningRuleSettings[Код],0))),INDEX(tblPlanningRuleSettings[Значение],MATCH("RESOURCE_BALANCE_RISK_PERCENT",tblPlanningRuleSettings[Код],0))>=0,INDEX(tblPlanningRuleSettings[Значение],MATCH("RESOURCE_BALANCE_RISK_PERCENT",tblPlanningRuleSettings[Код],0))<=1),INDEX(tblPlanningRuleSettings[Значение],MATCH("RESOURCE_BALANCE_RISK_PERCENT",tblPlanningRuleSettings[Код],0)),0.2),0.2)),1) | M4: =ROUND('02_Capacity'!$E$28-(SUMIFS(tblPlanActive[BE],tblPlanActive[Статус на конец квартала],"<>Готова аналитика",tblPlanActive[Статус на конец квартала],"<>Готова разработка (фронт)",tblPlanActive[Статус на конец квартала],"<>Отложено"))*(1+IFERROR(IF(AND(ISNUMBER(INDEX(tblPlanningRuleSettings[Значение],MATCH("RESOURCE_BALANCE_RISK_PERCENT",tblPlanningRuleSettings[Код],0))),INDEX(tblPlanningRuleSettings[Значение],MATCH("RESOURCE_BALANCE_RISK_PERCENT",tblPlanningRuleSettings[Код],0))>=0,INDEX(tblPlanningRuleSettings[Значение],MATCH("RESOURCE_BALANCE_RISK_PERCENT",tblPlanningRuleSettings[Код],0))<=1),INDEX(tblPlanningRuleSettings[Значение],MATCH("RESOURCE_BALANCE_RISK_PERCENT",tblPlanningRuleSettings[Код],0)),0.2),0.2)),1) | N4: =ROUND('02_Capacity'!$E$29-(SUMIFS(tblPlanActive[FE],tblPlanActive[Статус на конец квартала],"<>Готова аналитика",tblPlanActive[Статус на конец квартала],"<>Готова разработка (бэк)",tblPlanActive[Статус на конец квартала],"<>Отложено"))*(1+IFERROR(IF(AND(ISNUMBER(INDEX(tblPlanningRuleSettings[Значение],MATCH("RESOURCE_BALANCE_RISK_PERCENT",tblPlanningRuleSettings[Код],0))),INDEX(tblPlanningRuleSettings[Значение],MATCH("RESOURCE_BALANCE_RISK_PERCENT",tblPlanningRuleSettings[Код],0))>=0,INDEX(tblPlanningRuleSettings[Значение],MATCH("RESOURCE_BALANCE_RISK_PERCENT",tblPlanningRuleSettings[Код],0))<=1),INDEX(tblPlanningRuleSettings[Значение],MATCH("RESOURCE_BALANCE_RISK_PERCENT",tblPlanningRuleSettings[Код],0)),0.2),0.2)),1) | O4: =ROUND('02_Capacity'!$E$30-(SUMIFS(tblPlanActive[QA],tblPlanActive[Статус на конец квартала],"<>Готова аналитика",tblPlanActive[Статус на конец квартала],"<>Готова разработка",tblPlanActive[Статус на конец квартала],"<>Готова разработка (бэк)",tblPlanActive[Статус на конец квартала],"<>Готова разработка (фронт)",tblPlanActive[Статус на конец квартала],"<>Отложено"))*(1+IFERROR(IF(AND(ISNUMBER(INDEX(tblPlanningRuleSettings[Значение],MATCH("RESOURCE_BALANCE_RISK_PERCENT",tblPlanningRuleSettings[Код],0))),INDEX(tblPlanningRuleSettings[Значение],MATCH("RESOURCE_BALANCE_RISK_PERCENT",tblPlanningRuleSettings[Код],0))>=0,INDEX(tblPlanningRuleSettings[Значение],MATCH("RESOURCE_BALANCE_RISK_PERCENT",tblPlanningRuleSettings[Код],0))<=1),INDEX(tblPlanningRuleSettings[Значение],MATCH("RESOURCE_BALANCE_RISK_PERCENT",tblPlanningRuleSettings[Код],0)),0.2),0.2)),1)
A5: + | B5: \ | C5: - | D5: ↑ | E5: ↓ | F5: Приоритет | G5: Направление | H5: Описание | I5: ЗНИ/Jira | J5: Примечание | K5: DE | L5: AN | M5: BE | N5: FE | O5: QA | P5: Трудозатраты | Q5: Завершение (план) | R5: Релиз | S5: Статус на конец квартала | T5: Комментарий | U5: DE дни | V5: AN дни | W5: BE дни | X5: FE дни | Y5: QA дни | Z5: DE старт | AA5: DE финиш | AB5: AN старт | AC5: AN финиш | AD5: BE старт | AE5: BE финиш | AF5: FE старт | AG5: FE финиш | AH5: QA старт | AI5: QA финиш | AJ5: Диагностика
P6: =IF(COUNTA(G6:O6)=0,"",IFERROR(IF(K6="",0,CEILING(K6/'02_Capacity'!$E$25,1))+IF(L6="",0,CEILING(L6/'02_Capacity'!$E$20,1))+IF(M6="",0,CEILING(M6/'02_Capacity'!$E$20,1))+IF(N6="",0,CEILING(N6/'02_Capacity'!$E$20,1))+IF(O6="",0,CEILING(O6/'02_Capacity'!$E$20,1)),""))
P7: =IF(COUNTA(G7:O7)=0,"",IFERROR(IF(K7="",0,CEILING(K7/'02_Capacity'!$E$25,1))+IF(L7="",0,CEILING(L7/'02_Capacity'!$E$20,1))+IF(M7="",0,CEILING(M7/'02_Capacity'!$E$20,1))+IF(N7="",0,CEILING(N7/'02_Capacity'!$E$20,1))+IF(O7="",0,CEILING(O7/'02_Capacity'!$E$20,1)),""))
P8: =IF(COUNTA(G8:O8)=0,"",IFERROR(IF(K8="",0,CEILING(K8/'02_Capacity'!$E$25,1))+IF(L8="",0,CEILING(L8/'02_Capacity'!$E$20,1))+IF(M8="",0,CEILING(M8/'02_Capacity'!$E$20,1))+IF(N8="",0,CEILING(N8/'02_Capacity'!$E$20,1))+IF(O8="",0,CEILING(O8/'02_Capacity'!$E$20,1)),""))
P9: =IF(COUNTA(G9:O9)=0,"",IFERROR(IF(K9="",0,CEILING(K9/'02_Capacity'!$E$25,1))+IF(L9="",0,CEILING(L9/'02_Capacity'!$E$20,1))+IF(M9="",0,CEILING(M9/'02_Capacity'!$E$20,1))+IF(N9="",0,CEILING(N9/'02_Capacity'!$E$20,1))+IF(O9="",0,CEILING(O9/'02_Capacity'!$E$20,1)),""))
P10: =IF(COUNTA(G10:O10)=0,"",IFERROR(IF(K10="",0,CEILING(K10/'02_Capacity'!$E$25,1))+IF(L10="",0,CEILING(L10/'02_Capacity'!$E$20,1))+IF(M10="",0,CEILING(M10/'02_Capacity'!$E$20,1))+IF(N10="",0,CEILING(N10/'02_Capacity'!$E$20,1))+IF(O10="",0,CEILING(O10/'02_Capacity'!$E$20,1)),""))
P11: =IF(COUNTA(G11:O11)=0,"",IFERROR(IF(K11="",0,CEILING(K11/'02_Capacity'!$E$25,1))+IF(L11="",0,CEILING(L11/'02_Capacity'!$E$20,1))+IF(M11="",0,CEILING(M11/'02_Capacity'!$E$20,1))+IF(N11="",0,CEILING(N11/'02_Capacity'!$E$20,1))+IF(O11="",0,CEILING(O11/'02_Capacity'!$E$20,1)),""))
P12: =IF(COUNTA(G12:O12)=0,"",IFERROR(IF(K12="",0,CEILING(K12/'02_Capacity'!$E$25,1))+IF(L12="",0,CEILING(L12/'02_Capacity'!$E$20,1))+IF(M12="",0,CEILING(M12/'02_Capacity'!$E$20,1))+IF(N12="",0,CEILING(N12/'02_Capacity'!$E$20,1))+IF(O12="",0,CEILING(O12/'02_Capacity'!$E$20,1)),""))
P13: =IF(COUNTA(G13:O13)=0,"",IFERROR(IF(K13="",0,CEILING(K13/'02_Capacity'!$E$25,1))+IF(L13="",0,CEILING(L13/'02_Capacity'!$E$20,1))+IF(M13="",0,CEILING(M13/'02_Capacity'!$E$20,1))+IF(N13="",0,CEILING(N13/'02_Capacity'!$E$20,1))+IF(O13="",0,CEILING(O13/'02_Capacity'!$E$20,1)),""))
P14: =IF(COUNTA(G14:O14)=0,"",IFERROR(IF(K14="",0,CEILING(K14/'02_Capacity'!$E$25,1))+IF(L14="",0,CEILING(L14/'02_Capacity'!$E$20,1))+IF(M14="",0,CEILING(M14/'02_Capacity'!$E$20,1))+IF(N14="",0,CEILING(N14/'02_Capacity'!$E$20,1))+IF(O14="",0,CEILING(O14/'02_Capacity'!$E$20,1)),""))
P15: =IF(COUNTA(G15:O15)=0,"",IFERROR(IF(K15="",0,CEILING(K15/'02_Capacity'!$E$25,1))+IF(L15="",0,CEILING(L15/'02_Capacity'!$E$20,1))+IF(M15="",0,CEILING(M15/'02_Capacity'!$E$20,1))+IF(N15="",0,CEILING(N15/'02_Capacity'!$E$20,1))+IF(O15="",0,CEILING(O15/'02_Capacity'!$E$20,1)),""))
P16: =IF(COUNTA(G16:O16)=0,"",IFERROR(IF(K16="",0,CEILING(K16/'02_Capacity'!$E$25,1))+IF(L16="",0,CEILING(L16/'02_Capacity'!$E$20,1))+IF(M16="",0,CEILING(M16/'02_Capacity'!$E$20,1))+IF(N16="",0,CEILING(N16/'02_Capacity'!$E$20,1))+IF(O16="",0,CEILING(O16/'02_Capacity'!$E$20,1)),""))
P17: =IF(COUNTA(G17:O17)=0,"",IFERROR(IF(K17="",0,CEILING(K17/'02_Capacity'!$E$25,1))+IF(L17="",0,CEILING(L17/'02_Capacity'!$E$20,1))+IF(M17="",0,CEILING(M17/'02_Capacity'!$E$20,1))+IF(N17="",0,CEILING(N17/'02_Capacity'!$E$20,1))+IF(O17="",0,CEILING(O17/'02_Capacity'!$E$20,1)),""))
... P25: =IF(COUNTA(G25:O25)=0,"",IFERROR(IF(K25="",0,CEILING(K25/'02_Capacity'!$E$25,1))+IF(L25="",0,CEILING(L25/'02_Capacity'!$E$20,1))+IF(M25="",0,CEILING(M25/'02_Capacity'!$E$20,1))+IF(N25="",0,CEILING(N25/'02_Capacity'!$E$20,1))+IF(O25="",0,CEILING(O25/'02_Capacity'!$E$20,1)),""))
A28: Серая зона
I29: JQL
A30: + | B30: \ | C30: - | D30: ↑ | E30: ↓ | F30: Приоритет | G30: Направление | H30: Описание | I30: ЗНИ/Jira | J30: Примечание | K30: DE | L30: AN | M30: BE | N30: FE | O30: QA | P30: Трудозатраты | Q30: Завершение (план) | R30: Релиз | S30: Статус на конец квартала | T30: Комментарий | U30: DE дни | V30: AN дни | W30: BE дни | X30: FE дни | Y30: QA дни | Z30: DE старт | AA30: DE финиш | AB30: AN старт | AC30: AN финиш | AD30: BE старт | AE30: BE финиш | AF30: FE старт | AG30: FE финиш | AH30: QA старт | AI30: QA финиш | AJ30: Диагностика
P31: =IF(COUNTA(G31:O31)=0,"",IFERROR(IF(K31="",0,CEILING(K31/'02_Capacity'!$E$25,1))+IF(L31="",0,CEILING(L31/'02_Capacity'!$E$20,1))+IF(M31="",0,CEILING(M31/'02_Capacity'!$E$20,1))+IF(N31="",0,CEILING(N31/'02_Capacity'!$E$20,1))+IF(O31="",0,CEILING(O31/'02_Capacity'!$E$20,1)),""))
P32: =IF(COUNTA(G32:O32)=0,"",IFERROR(IF(K32="",0,CEILING(K32/'02_Capacity'!$E$25,1))+IF(L32="",0,CEILING(L32/'02_Capacity'!$E$20,1))+IF(M32="",0,CEILING(M32/'02_Capacity'!$E$20,1))+IF(N32="",0,CEILING(N32/'02_Capacity'!$E$20,1))+IF(O32="",0,CEILING(O32/'02_Capacity'!$E$20,1)),""))
P33: =IF(COUNTA(G33:O33)=0,"",IFERROR(IF(K33="",0,CEILING(K33/'02_Capacity'!$E$25,1))+IF(L33="",0,CEILING(L33/'02_Capacity'!$E$20,1))+IF(M33="",0,CEILING(M33/'02_Capacity'!$E$20,1))+IF(N33="",0,CEILING(N33/'02_Capacity'!$E$20,1))+IF(O33="",0,CEILING(O33/'02_Capacity'!$E$20,1)),""))
P34: =IF(COUNTA(G34:O34)=0,"",IFERROR(IF(K34="",0,CEILING(K34/'02_Capacity'!$E$25,1))+IF(L34="",0,CEILING(L34/'02_Capacity'!$E$20,1))+IF(M34="",0,CEILING(M34/'02_Capacity'!$E$20,1))+IF(N34="",0,CEILING(N34/'02_Capacity'!$E$20,1))+IF(O34="",0,CEILING(O34/'02_Capacity'!$E$20,1)),""))
P35: =IF(COUNTA(G35:O35)=0,"",IFERROR(IF(K35="",0,CEILING(K35/'02_Capacity'!$E$25,1))+IF(L35="",0,CEILING(L35/'02_Capacity'!$E$20,1))+IF(M35="",0,CEILING(M35/'02_Capacity'!$E$20,1))+IF(N35="",0,CEILING(N35/'02_Capacity'!$E$20,1))+IF(O35="",0,CEILING(O35/'02_Capacity'!$E$20,1)),""))
P36: =IF(COUNTA(G36:O36)=0,"",IFERROR(IF(K36="",0,CEILING(K36/'02_Capacity'!$E$25,1))+IF(L36="",0,CEILING(L36/'02_Capacity'!$E$20,1))+IF(M36="",0,CEILING(M36/'02_Capacity'!$E$20,1))+IF(N36="",0,CEILING(N36/'02_Capacity'!$E$20,1))+IF(O36="",0,CEILING(O36/'02_Capacity'!$E$20,1)),""))
P37: =IF(COUNTA(G37:O37)=0,"",IFERROR(IF(K37="",0,CEILING(K37/'02_Capacity'!$E$25,1))+IF(L37="",0,CEILING(L37/'02_Capacity'!$E$20,1))+IF(M37="",0,CEILING(M37/'02_Capacity'!$E$20,1))+IF(N37="",0,CEILING(N37/'02_Capacity'!$E$20,1))+IF(O37="",0,CEILING(O37/'02_Capacity'!$E$20,1)),""))
P38: =IF(COUNTA(G38:O38)=0,"",IFERROR(IF(K38="",0,CEILING(K38/'02_Capacity'!$E$25,1))+IF(L38="",0,CEILING(L38/'02_Capacity'!$E$20,1))+IF(M38="",0,CEILING(M38/'02_Capacity'!$E$20,1))+IF(N38="",0,CEILING(N38/'02_Capacity'!$E$20,1))+IF(O38="",0,CEILING(O38/'02_Capacity'!$E$20,1)),""))
P39: =IF(COUNTA(G39:O39)=0,"",IFERROR(IF(K39="",0,CEILING(K39/'02_Capacity'!$E$25,1))+IF(L39="",0,CEILING(L39/'02_Capacity'!$E$20,1))+IF(M39="",0,CEILING(M39/'02_Capacity'!$E$20,1))+IF(N39="",0,CEILING(N39/'02_Capacity'!$E$20,1))+IF(O39="",0,CEILING(O39/'02_Capacity'!$E$20,1)),""))
P40: =IF(COUNTA(G40:O40)=0,"",IFERROR(IF(K40="",0,CEILING(K40/'02_Capacity'!$E$25,1))+IF(L40="",0,CEILING(L40/'02_Capacity'!$E$20,1))+IF(M40="",0,CEILING(M40/'02_Capacity'!$E$20,1))+IF(N40="",0,CEILING(N40/'02_Capacity'!$E$20,1))+IF(O40="",0,CEILING(O40/'02_Capacity'!$E$20,1)),""))
P41: =IF(COUNTA(G41:O41)=0,"",IFERROR(IF(K41="",0,CEILING(K41/'02_Capacity'!$E$25,1))+IF(L41="",0,CEILING(L41/'02_Capacity'!$E$20,1))+IF(M41="",0,CEILING(M41/'02_Capacity'!$E$20,1))+IF(N41="",0,CEILING(N41/'02_Capacity'!$E$20,1))+IF(O41="",0,CEILING(O41/'02_Capacity'!$E$20,1)),""))
P42: =IF(COUNTA(G42:O42)=0,"",IFERROR(IF(K42="",0,CEILING(K42/'02_Capacity'!$E$25,1))+IF(L42="",0,CEILING(L42/'02_Capacity'!$E$20,1))+IF(M42="",0,CEILING(M42/'02_Capacity'!$E$20,1))+IF(N42="",0,CEILING(N42/'02_Capacity'!$E$20,1))+IF(O42="",0,CEILING(O42/'02_Capacity'!$E$20,1)),""))
... P50: =IF(COUNTA(G50:O50)=0,"",IFERROR(IF(K50="",0,CEILING(K50/'02_Capacity'!$E$25,1))+IF(L50="",0,CEILING(L50/'02_Capacity'!$E$20,1))+IF(M50="",0,CEILING(M50/'02_Capacity'!$E$20,1))+IF(N50="",0,CEILING(N50/'02_Capacity'!$E$20,1))+IF(O50="",0,CEILING(O50/'02_Capacity'!$E$20,1)),""))
A53: Бэклог
A54: ++ | I54: JQL
A55: + | B55: \ | C55: - | D55: ↑ | E55: ↓ | F55: Приоритет | G55: Направление | H55: Описание | I55: ЗНИ/Jira | J55: Примечание | K55: DE | L55: AN | M55: BE | N55: FE | O55: QA | P55: Трудозатраты | Q55: Завершение (план) | R55: Релиз | S55: Статус на конец квартала | T55: Комментарий | U55: DE дни | V55: AN дни | W55: BE дни | X55: FE дни | Y55: QA дни | Z55: DE старт | AA55: DE финиш | AB55: AN старт | AC55: AN финиш | AD55: BE старт | AE55: BE финиш | AF55: FE старт | AG55: FE финиш | AH55: QA старт | AI55: QA финиш | AJ55: Диагностика
A56: + | F56: 10 | G56: Личный кабинет | H56: Единый вход для пользователей | I56: PLAN-1001 | J56: Демо | K56: 4 | L56: 3 | M56: 5 | N56: 5 | O56: 4 | P56: =IF(COUNTA(G56:O56)=0,"",IFERROR(IF(K56="",0,CEILING(K56/'02_Capacity'!$E$25,1))+IF(L56="",0,CEILING(L56/'02_Capacity'!$E$20,1))+IF(M56="",0,CEILING(M56/'02_Capacity'!$E$20,1))+IF(N56="",0,CEILING(N56/'02_Capacity'!$E$20,1))+IF(O56="",0,CEILING(O56/'02_Capacity'!$E$20,1)),""))
A57: + | F57: 20 | G57: Уведомления | H57: Настройка email-уведомлений | I57: PLAN-1002 | K57: 2 | L57: 4 | M57: 6 | N57: 3 | O57: 4 | P57: =IF(COUNTA(G57:O57)=0,"",IFERROR(IF(K57="",0,CEILING(K57/'02_Capacity'!$E$25,1))+IF(L57="",0,CEILING(L57/'02_Capacity'!$E$20,1))+IF(M57="",0,CEILING(M57/'02_Capacity'!$E$20,1))+IF(N57="",0,CEILING(N57/'02_Capacity'!$E$20,1))+IF(O57="",0,CEILING(O57/'02_Capacity'!$E$20,1)),""))
A58: + | F58: 30 | G58: Каталог | H58: Поиск и фильтрация элементов | I58: PLAN-1003 | K58: 5 | L58: 5 | M58: 8 | N58: 6 | O58: 6 | P58: =IF(COUNTA(G58:O58)=0,"",IFERROR(IF(K58="",0,CEILING(K58/'02_Capacity'!$E$25,1))+IF(L58="",0,CEILING(L58/'02_Capacity'!$E$20,1))+IF(M58="",0,CEILING(M58/'02_Capacity'!$E$20,1))+IF(N58="",0,CEILING(N58/'02_Capacity'!$E$20,1))+IF(O58="",0,CEILING(O58/'02_Capacity'!$E$20,1)),""))
...

Sheet 99_Правила планирования
A1: Правила планирования
A3: Экспертиза | B3: Название | C3: Waterfall порядок
A4: AN | B4: Аналитика | C4: 1
A5: DE | B5: Дизайн | C5: 1
A6: BE | B6: Backend-разработка | C6: 2
A7: FE | B7: Frontend-разработка | C7: 3
A8: QA | B8: Тестирование | C8: 4
A11: Правила квартального планирования
A13: Правило | B13: Описание
A14: Единица оценки | B14: Оценки задач указаны в человеко-днях.
A15: Источник задач | B15: Первичный источник задач: лист 03_Оценка задач.
A16: Стартовое состояние | B16: При первичной сборке все задачи попадают в бэклог.
A17: Переходы | B17: Бэклог -> План; План -> Серая зона; План -> Бэклог; Серая зона -> Бэклог.
A18: Трудозатраты | B18: Трудозатраты показывают нормализованные человеко-дни: DE = CEILING(DE / фокус-фактор дизайнеров, 1), остальные этапы = CEILING(оценка / фокус-фактор основной команды, 1).
A19: Календарная длительность | B19: Календарные длительности рассчитываются по дням доступности сотрудников и могут быть больше трудозатрат из-за аллокации и отпусков.
A20: Пустые оценки | B20: Пустые DE/AN/BE/FE/QA считаются нулем.
A21: Фокус-фактор DE | B21: Для DE используется отдельный фокус-фактор дизайнеров с листа 02_Capacity; он применяется и к трудозатратам, и к дневному прогрессу.
A22: Ресурсы AN | B22: AN выполняют аналитики и лид по аналитике.
A23: Ресурсы DE | B23: DE выполняют сотрудники с ролью Дизайнер.
A24: Ресурсы BE | B24: BE выполняют BE-разработчики и тим-лид / техлид.
... A33: QA overlap | B33: Половина QA может стартовать после завершения аналитики; вторая половина QA стартует после завершения BE и FE.
A35: Код | B35: Правило | C35: Значение | D35: Ед. | E35: Описание
A36: AN_BE_MIN_WORKDAYS | B36: AN -> BE: минимальный лаг | C36: 5 | D36: раб. дни | E36: Минимум рабочих дней от старта AN до возможного старта BE для длинной аналитики.
A37: AN_BE_COMPLETION_PERCENT | B37: AN -> BE: готовность AN | C37: 0.5 | D37: % | E37: Доля расчетной длительности AN, после которой BE может стартовать для длинной аналитики.
A38: BE_FE_MIN_WORKDAYS | B38: BE -> FE: минимальный лаг | C38: 5 | D38: раб. дни | E38: Минимум рабочих дней от старта BE до возможного старта FE для длинной backend-разработки.
A39: BE_FE_COMPLETION_PERCENT | B39: BE -> FE: готовность BE | C39: 0.5 | D39: % | E39: Доля расчетной длительности BE, после которой FE может стартовать для длинной backend-разработки.
A40: QA_FIRST_PART_PERCENT | B40: QA: первая часть | C40: 0.5 | D40: % | E40: Доля QA, которая может выполняться после завершения аналитики.
A41: RESOURCE_BALANCE_RISK_PERCENT | B41: Баланс ресурсов: риск | C41: 0.2 | D41: % | E41: Риск, добавляемый к оценкам активного плана при расчете баланса ресурсов.

Sheet 100_Шаблон экспресс оценки
A1: Форма оценки трудозатрат | M1: Легенда
D2: Номер задачи в Jira | M2: Наличие БТ/Концепции | N2: Отсутствует или в наличии краткая Постановка задачи
D3: Название задачи в Jira | M3: Ответственность | N3: Эксперт, подготовивший оценку трудозатрат, несёт за неё персональную ответственность за результат. Требуется учитывать, что любую предоставленную оценку необходимо уметь защитить.
D4: Документы, на основании которых произведена оценка | M4: Декомпозиция | N4: Достаточный уровень декомпозиции - верхнеуровневое деление на функции
D5: Версия оценки | M5: Подход к оценке | N5: Существует три вида оценки – оптимистичная, реалистичная, пессимистичная. Для оценки используем реалистичный вид.
D6: Дата оценки | M6: Консультации | N6: В случае, если по оцениваемой задаче не было схожего опыта реализации, то необходимо обращаться к руководителям направлений и другим более опытным коллегам за консультацией по оценке.
D7: ФИО архитектора, участвовавшего в разработке решения
D8: ФИО ИТ-лидера
D9: ФИО аналитика, выполнившего оценку
D10: ФИО Back-разработчика, выполнившего оценку
D11: ФИО Front-разработчика, выполнившего оценку
D12: ФИО QA, выполнившего оценку
D13: ФИО дизайнера, выполнившего оценку
A15: Epic/ Story Group/ Story/Разрабатываемые в истории требования | E15: Приоритет | F15: Задача в Jira | G15: Человеко-часы | P15: Человеко-дни(автоматический расчёт)
G16: AN | H16: Design | I16: BE | J16: FE | K16: QA | L16: Комментарии | N16: РП (человеко-часы) | P16: Аналитика | Q16: Design | R16: BE | S16: FE | T16: QA | U16: Архитектор | V16: DevOPS + OPS | W16: РП
A17: [0] YYY | G17: =G18+G21 -> 10 | H17: =H18+H21 -> 10 | I17: =I18+I21 -> 10 | J17: =J18+J21 -> 10 | K17: =K18+K21 -> 10 | N17: 5 | P17: =ROUNDUP(G17/8,0) -> 2 | Q17: =ROUNDUP(H17/8,0) -> 2 | R17: =ROUNDUP(I17/8,0) -> 2 | S17: =ROUNDUP(J17/8,0) -> 2 | T17: =ROUNDUP(K17/8,0) -> 2 | U17: =ROUNDUP(N19/8,0) -> 4 | W17: =ROUNDUP(N17/8,0) -> 1
B18: [1] YYY | G18: =SUM(G19:G20) -> 3 | H18: =SUM(H19:H20) -> 3 | I18: =SUM(I19:I20) -> 3 | J18: =SUM(J19:J20) -> 3 | K18: =SUM(K19:K20) -> 3 | N18: Архитекто (чч)
C19: [2] Разработка и согласование в АСДД схемы сквозного бизнес-процесса | G19: 1 | H19: 1 | I19: 1 | J19: 1 | K19: 1 | N19: 25
C20: [2] ЖЦ заявки | G20: 2 | H20: 2 | I20: 2 | J20: 2 | K20: 2
B21: [1] YYY | G21: =SUM(G22:G23) -> 7 | H21: =SUM(H22:H23) -> 7 | I21: =SUM(I22:I23) -> 7 | J21: =SUM(J22:J23) -> 7 | K21: =SUM(K22:K23) -> 7
C22: [2] Разработка и согласование в АСДД схемы сквозного бизнес-процесса | G22: 3 | H22: 3 | I22: 3 | J22: 3 | K22: 3
C23: [2] ЖЦ заявки | G23: 4 | H23: 4 | I23: 4 | J23: 4 | K23: 4

Sheet 101_Списки
A1: Списки
A3: Артефакты | C3: Смежники | E3: Статусы | G3: Да/Нет
A4: БТ | C4: Echo | E4: Готова аналитика | G4: Да
A5: Макеты | C5: Sierra | E5: Готова разработка | G5: Нет
A6: ОТАР | C6: Bravo | E6: Готова разработка (бэк)
A7: ПСИ ИБ | C7: Foxtrot | E7: Готова разработка (фронт)
C8: Uniform | E8: Готово к релизу
C9: India | E9: ПРОМ
C10: Ф1 | E10: Отложено
C11: ЕСК
C12: Тесса
